package Exception3;

import java.util.InputMismatchException;
import java.util.Scanner;

public class Exception {

	/*
	 * try { } : 예외가 발생되는 영역 catch(try에서 발생된 예외객체 참조) {} : 발생된 예외를 잡아 처리하는 영역
	 * finally { } : 예외 발생 여부와 관계 없이 무조건 실행되는 영역(자원 해제 용도)
	 * 
	 * throw : 예외 객체를 던지는 키워드 throws : 메서드에서 발생되는 예외를 명시(예외 전가)
	 */
	public static void main(String[] args) {
		Scanner in = new Scanner(System.in);

		System.out.print("수 입력:");
		int n1 = 0, n2 = 0, ret = 0;

		try {
			n1 = in.nextInt(); // InputMismatchException
		} catch (InputMismatchException e) {
			 System.out.println("입력에 문제가 있다.");
			// System.out.println(e.getMessage());
		}

		System.out.print("수 입력:");
		try {
			n2 = in.nextInt(); // InputMismatchException
		} catch (InputMismatchException e) {
			// System.out.println("입력에 문제가 있다.");
			// e.printStackTrace(); //이것만 거의 사용
		}

		try {
			ret = n1 / n2; // ArithmeticException
		} catch (ArithmeticException e) {
			// System.out.println("0으로 나눌 수 없음 : " + e.getMessage());
		}
		System.out.println("결과:" + ret);
	}
}